Workbook

Sheet README
A1: NEMSIS 3.5 → IHE EMS FHIR — Source-to-Target Mapping Workbook
A3: Project | B3: nemsis2FHIR — robust NEMSIS 3.5 ePCR → IHE EMS (mPSC / US Core R4) translation engine
A4: Author | B4: FHIRmedic (Chad), prepared with Claude
A5: Date | B5: 2026-08-06
A6: Status | B6: Draft superset mapping for review — upstream-ready (IHE PCC / HL7 EMS WG)
A7: Companion docs | B7: 01_Architecture_Design.md · 03_ADRs.md · 04_Phased_Roadmap.md
A9: WHY THIS EXISTS | B9: The IHE PCC mPSC IG (build.fhir.org/ig/IHE/PCC.PCS) publishes a NEMSIS→FHIR page, but its FHIR-target column is populated for only ~11 of ~330 element rows (dAgency→Organization, eCustomConfiguration→Observation; eOutcome punted to external QORE). This workbook AUTHORS the missing clinical mapping as a complete superset.
A10: TARGET MODEL | B10: Layered (ADR-001): NEMSIS → canonical US-Core-aligned FHIR R4 resource graph (Layer A, the durable asset) → assembled into the mPSC IPS Document Bundle (Layer B). Column 'mPSC Section' shows the document home; '*' marks a section we PROPOSE upstream (mPSC currently defines only Problems/Allergies/Medications/Payers).
A12: HOW TO READ A PANEL TAB | B12: One row per NEMSIS element (or element range). Columns: NEMSIS ID · Name · Usage/Card · Repeats(group) · Target FHIR Resource · Target Profile · FHIR Path · Datatype Transform · Terminology/ConceptMap · NV handling · PN handling · mPSC Section · Status · Notes.
A13: STATUS values | B13: Status = mapping completeness: Mapped = full target defined here · Seeded = target assigned, path indicative, needs refinement · Deferred = out of scope this phase (e.g., eOutcome→QORE, billing detail, telematics). UPSTREAM proposals are tracked separately: a '*' on the mPSC Section marks a section we propose adding to the IG, and the Gap_Register tab enumerates every proposed addition/defect.
A14: NV handling | B14: NEMSIS Not-Values (7701xxx: Not Applicable/Not Recorded/Not Reporting) carried on xsi:nil elements → FHIR data-absent-reason, and escalated to Composition.section.emptyReason at section level. NEVER fabricated as a real value.
A15: PN handling | B15: NEMSIS Pertinent-Negatives (8801xxx: contraindicated/refused/No Known Drug Allergy) → negation semantics (status=not-done + statusReason, negated AllergyIntolerance, negative Observation.interpretation). NEVER dropped — the negative IS the clinical content.
A16: Repeating groups | B16: eVitals.VitalGroup / eMedications.MedicationGroup / eProcedures.ProcedureGroup etc. → one FHIR resource per group instance, all sharing the group's .01 timestamp (see Architecture §4.3).
... A21: NOT A RUNTIME ARTIFACT | B21: This workbook is the human-readable spec. The executable form is FHIR StructureMaps + ConceptMaps, executed natively in a Python mapper that POSTs FHIR transaction Bundles to fhirEngine (Chad's OSS FHIR R4 server on OSS Delta Lake); no Databricks/Spark (ADR-002/009/010). ConceptMaps are applied in the mapper (fhirEngine has no $translate); resulting ValueSets/CodeSystems are loaded into fhirEngine for $validate-code. This workbook is the source of truth and review surface for those maps.

Sheet Coverage_Matrix
A1: Coverage Matrix — status counts per panel (live COUNTIF over each tab)
A3: Panel tab | B3: Primary FHIR target(s) | C3: Mapped | D3: Seeded | E3: Deferred | F3: Upstream | G3: Total rows
A4: Admin_Org_Crew | B4: Composition/Organization/Practitioner/Provenance | C4: =COUNTIF(Admin_Org_Crew!$M:$M,"Mapped") | D4: =COUNTIF(Admin_Org_Crew!$M:$M,"Seeded") | E4: =COUNTIF(Admin_Org_Crew!$M:$M,"Deferred") | F4: =COUNTIF(Admin_Org_Crew!$M:$M,"Upstream") | G4: =SUM(C4:F4)
A5: Encounter | B5: Encounter (spine) / Location | C5: =COUNTIF(Encounter!$M:$M,"Mapped") | D5: =COUNTIF(Encounter!$M:$M,"Seeded") | E5: =COUNTIF(Encounter!$M:$M,"Deferred") | F5: =COUNTIF(Encounter!$M:$M,"Upstream") | G5: =SUM(C5:F5)
A6: ePatient | B6: Patient (US Core / IHE PCC) | C6: =COUNTIF(ePatient!$M:$M,"Mapped") | D6: =COUNTIF(ePatient!$M:$M,"Seeded") | E6: =COUNTIF(ePatient!$M:$M,"Deferred") | F6: =COUNTIF(ePatient!$M:$M,"Upstream") | G6: =SUM(C6:F6)
A7: eSituation_eInjury | B7: Condition / Observation | C7: =COUNTIF(eSituation_eInjury!$M:$M,"Mapped") | D7: =COUNTIF(eSituation_eInjury!$M:$M,"Seeded") | E7: =COUNTIF(eSituation_eInjury!$M:$M,"Deferred") | F7: =COUNTIF(eSituation_eInjury!$M:$M,"Upstream") | G7: =SUM(C7:F7)
A8: eArrest | B8: Observation / Procedure | C8: =COUNTIF(eArrest!$M:$M,"Mapped") | D8: =COUNTIF(eArrest!$M:$M,"Seeded") | E8: =COUNTIF(eArrest!$M:$M,"Deferred") | F8: =COUNTIF(eArrest!$M:$M,"Upstream") | G8: =SUM(C8:F8)
A9: eHistory | B9: Condition / Allergy / MedicationStatement / Consent | C9: =COUNTIF(eHistory!$M:$M,"Mapped") | D9: =COUNTIF(eHistory!$M:$M,"Seeded") | E9: =COUNTIF(eHistory!$M:$M,"Deferred") | F9: =COUNTIF(eHistory!$M:$M,"Upstream") | G9: =SUM(C9:F9)
A10: eVitals | B10: Observation (US Core Vital Signs) | C10: =COUNTIF(eVitals!$M:$M,"Mapped") | D10: =COUNTIF(eVitals!$M:$M,"Seeded") | E10: =COUNTIF(eVitals!$M:$M,"Deferred") | F10: =COUNTIF(eVitals!$M:$M,"Upstream") | G10: =SUM(C10:F10)
A11: eMedications | B11: MedicationAdministration | C11: =COUNTIF(eMedications!$M:$M,"Mapped") | D11: =COUNTIF(eMedications!$M:$M,"Seeded") | E11: =COUNTIF(eMedications!$M:$M,"Deferred") | F11: =COUNTIF(eMedications!$M:$M,"Upstream") | G11: =SUM(C11:F11)
A12: eProcedures_eAirway | B12: Procedure | C12: =COUNTIF(eProcedures_eAirway!$M:$M,"Mapped") | D12: =COUNTIF(eProcedures_eAirway!$M:$M,"Seeded") | E12: =COUNTIF(eProcedures_eAirway!$M:$M,"Deferred") | F12: =COUNTIF(eProcedures_eAirway!$M:$M,"Upstream") | G12: =SUM(C12:F12)
A13: eExam_eLabs_eDevice | B13: Observation / DiagnosticReport / Media | C13: =COUNTIF(eExam_eLabs_eDevice!$M:$M,"Mapped") | D13: =COUNTIF(eExam_eLabs_eDevice!$M:$M,"Seeded") | E13: =COUNTIF(eExam_eLabs_eDevice!$M:$M,"Deferred") | F13: =COUNTIF(eExam_eLabs_eDevice!$M:$M,"Upstream") | G13: =SUM(C13:F13)
A14: eDisposition | B14: Encounter / Location / Communication | C14: =COUNTIF(eDisposition!$M:$M,"Mapped") | D14: =COUNTIF(eDisposition!$M:$M,"Seeded") | E14: =COUNTIF(eDisposition!$M:$M,"Deferred") | F14: =COUNTIF(eDisposition!$M:$M,"Upstream") | G14: =SUM(C14:F14)
A15: ePayment | B15: Coverage / Contract | C15: =COUNTIF(ePayment!$M:$M,"Mapped") | D15: =COUNTIF(ePayment!$M:$M,"Seeded") | E15: =COUNTIF(ePayment!$M:$M,"Deferred") | F15: =COUNTIF(ePayment!$M:$M,"Upstream") | G15: =SUM(C15:F15)
A16: eOutcome | B16: (external QORE) — deferred | C16: =COUNTIF(eOutcome!$M:$M,"Mapped") | D16: =COUNTIF(eOutcome!$M:$M,"Seeded") | E16: =COUNTIF(eOutcome!$M:$M,"Deferred") | F16: =COUNTIF(eOutcome!$M:$M,"Upstream") | G16: =SUM(C16:F16)
A17: eNarrative_eOther | B17: Composition.text / DocumentReference / Provenance | C17: =COUNTIF(eNarrative_eOther!$M:$M,"Mapped") | D17: =COUNTIF(eNarrative_eOther!$M:$M,"Seeded") | E17: =COUNTIF(eNarrative_eOther!$M:$M,"Deferred") | F17: =COUNTIF(eNarrative_eOther!$M:$M,"Upstream") | G17: =SUM(C17:F17)
A18: TOTAL | B18: all national panels | C18: =SUM(C4:C17) | D18: =SUM(D4:D17) | E18: =SUM(E4:E17) | F18: =SUM(F4:F17) | G18: =SUM(G4:G17)
A20: Note: | B20: Row counts are mapping ROWS; many rows cover an element RANGE (e.g. eExam.04-.25, eInjury.11-.29), so covered NEMSIS elements far exceed row counts. 'Deferred' concentrates in eOutcome (→QORE), billing (ePayment), and telematics/waveforms (ACN, eDevice, eLabs imaging) — all intentional, none silently dropped.

Sheet Admin_Org_Crew
A1: eRecord · dAgency · dPersonnel · eCrew · eCustom → Composition / Organization / Practitioner / Provenance
A3: NEMSIS ID | B3: NEMSIS Element Name | C3: Usage/Card | D3: Repeats | E3: Target FHIR Resource | F3: Target Profile | G3: FHIR Path | H3: Datatype Transform | I3: Terminology / ConceptMap | J3: NV handling | K3: PN handling | L3: mPSC Section | M3: Status | N3: Notes
A4: eRecord.01 | B4: Patient Care Report Number | C4: M [1..1] | D4: No | E4: Composition / Bundle | F4: IHE.PCC.FHIR.MS.Composition | G4: Composition.identifier; Bundle.identifier | H4: string→Identifier | I4: system=urn:nemsis:pcr | J4: n/a | K4: n/a | L4: (header) | M4: Mapped | N4: PCR business key; also Provenance target
A5: eRecord.02 | B5: Software Creator | C5: M [1..1] | D5: No | E5: Device / Provenance | F5: — | G5: Device.manufacturer; Provenance.entity | H5: string | I5: — | J5: n/a | K5: n/a | L5: (header) | M5: Seeded | N5: Source-software attribution
A6: eRecord.03 | B6: Software Name | C6: M [1..1] | D6: No | E6: Device | F6: — | G6: Device.deviceName.name | H6: string | I6: — | J6: n/a | K6: n/a | L6: (header) | M6: Seeded
A7: eRecord.04 | B7: Software Version | C7: M [1..1] | D7: No | E7: Device | F7: — | G7: Device.version.value | H7: string | I7: — | J7: n/a | K7: n/a | L7: (header) | M7: Seeded
A8: dAgency.01 | B8: EMS Agency Unique State ID | C8: M [1..1] | D8: No | E8: Organization | F8: US Core Organization | G8: Organization.identifier | H8: string→Identifier | I8: system=state agency id | J8: n/a | K8: n/a | L8: (author) | M8: Mapped | N8: IG-ANCHORED mapping (only populated cells in mPSC)
A9: dAgency.02 | B9: EMS Agency Number | C9: M [1..1] | D9: No | E9: Organization | F9: US Core Organization | G9: Organization.identifier | H9: string→Identifier | I9: system=NASEMSO/national | J9: n/a | K9: n/a | L9: (author) | M9: Mapped | N9: IG-ANCHORED
A10: dAgency.03 | B10: EMS Agency Name | C10: RE [0..1] | D10: No | E10: Organization | F10: US Core Organization | G10: Organization.name | H10: string | I10: n/a | J10: NV(7701xxx)→data-absent-reason | K10: n/a | L10: (author) | M10: Mapped | N10: IG-ANCHORED
A11: dAgency.04 | B11: EMS Agency State | C11: M [1..1] | D11: No | E11: Organization | F11: US Core Organization | G11: Organization.address.state | H11: string→address | I11: USPS state | J11: n/a | K11: n/a | L11: (author) | M11: Mapped | N11: IG-ANCHORED
A12: dAgency.25 | B12: National Provider Identifier (NPI) | C12: O | D12: No | E12: Organization | F12: US Core Organization | G12: Organization.identifier (NPI) | H12: string→Identifier | I12: system=http://hl7.org/fhir/sid/us-npi | J12: NV(7701xxx)→data-absent-reason | K12: n/a | L12: (author) | M12: Mapped
A13: dPersonnel.* | B13: Personnel roster / certifications | C13: varies | D13: Yes | E13: Practitioner + PractitionerRole | F13: US Core Practitioner/Role | G13: Practitioner.identifier/name; PractitionerRole.code | H13: group→resource | I13: cert level ConceptMap | J13: NV(7701xxx)→data-absent-reason | K13: n/a | L13: (author) | M13: Seeded | N13: Referenced by eMedications.09/eProcedures.09 crew IDs
A14: eCrew.01 | B14: Crew Member ID | C14: RE [0..1] | D14: Yes | E14: PractitionerRole | F14: US Core PractitionerRole | G14: PractitionerRole.practitioner→dPersonnel | H14: string→ref | I14: links to dPersonnel | J14: NV(7701xxx)→data-absent-reason | K14: n/a | L14: (author) | M14: Mapped
A15: eCrew.02 | B15: Crew Member Level | C15: RE [0..1] | D15: Yes | E15: PractitionerRole | F15: US Core PractitionerRole | G15: PractitionerRole.code | H15: code | I15: cert-level ConceptMap | J15: NV(7701xxx)→data-absent-reason | K15: n/a | L15: (author) | M15: Mapped
A16: eCrew.03 | B16: Crew Member Response Role | C16: RE [0..*] | D16: Yes | E16: PractitionerRole | F16: US Core PractitionerRole | G16: PractitionerRole.specialty/code | H16: code | I16: response-role ConceptMap | J16: NV(7701xxx)→data-absent-reason | K16: n/a | L16: (author) | M16: Mapped
A17: eCustomConfiguration.01-.09 | B17: Custom element definitions | C17: varies | D17: Yes | E17: Observation (definition) | F17: — | G17: Observation / Observation.value[x] / dataAbsentReason | H17: per IG | I17: local | J17: NV(7701xxx)→data-absent-reason | K17: PN(8801xxx)→statusReason/negation | L17: (author) | M17: Mapped | N17: IG-ANCHORED to Observation; .07 NV→valueCodeableConcept, .08 PN→dataAbsentReason, .09 grouping→identifier
A18: eCustomResults.01-.03 | B18: Custom element results | C18: varies | D18: Yes | E18: Observation | F18: — | G18: Observation.value[x]; CorrelationID→derivedFrom | H18: per IG | I18: local | J18: NV(7701xxx)→data-absent-reason | K18: PN(8801xxx)→statusReason/negation | L18: Results | M18: Mapped | N18: CorrelationID links result↔config (.02 ref, .03 correlation)

Sheet Encounter
A1: eResponse · eDispatch · eTimes · eScene → Encounter (spine) / Location
A3: NEMSIS ID | B3: NEMSIS Element Name | C3: Usage/Card | D3: Repeats | E3: Target FHIR Resource | F3: Target Profile | G3: FHIR Path | H3: Datatype Transform | I3: Terminology / ConceptMap | J3: NV handling | K3: PN handling | L3: mPSC Section | M3: Status | N3: Notes
A4: eResponse.01 | B4: EMS Agency Number | C4: M [1..1] | D4: No | E4: Encounter/Organization | F4: US Core Encounter | G4: Encounter.serviceProvider→Organization | H4: ref | I4: — | J4: NV(7701xxx)→data-absent-reason | K4: n/a | L4: EMS Course* | M4: Mapped | N4: Ties Encounter to Organization
A5: eResponse.03 | B5: Incident Number | C5: R [1..1] | D5: No | E5: Encounter | F5: US Core Encounter | G5: Encounter.identifier | H5: string→Identifier | I5: system=incident | J5: NV(7701xxx)→data-absent-reason | K5: n/a | L5: EMS Course* | M5: Mapped
A6: eResponse.04 | B6: EMS Response Number | C6: R [1..1] | D6: No | E6: Encounter | F6: US Core Encounter | G6: Encounter.identifier | H6: string→Identifier | I6: system=response | J6: NV(7701xxx)→data-absent-reason | K6: n/a | L6: EMS Course* | M6: Mapped
A7: eResponse.05 | B7: Type of Service Requested | C7: M [1..1] | D7: No | E7: Encounter | F7: US Core Encounter | G7: Encounter.type / serviceType | H7: code | I7: service-type ConceptMap | J7: NV(7701xxx)→data-absent-reason | K7: n/a | L7: EMS Course* | M7: Mapped
A8: eResponse.07 | B8: Unit Transport & Equipment Capability | C8: M [1..1] | D8: No | E8: Encounter | F8: — | G8: Encounter.type (secondary) | H8: code | I8: ConceptMap→SNOMED | J8: NV(7701xxx)→data-absent-reason | K8: n/a | L8: EMS Course* | M8: Seeded
A9: eResponse.08-.12 | B9: Dispatch/Response/Scene/Transport/Turnaround Delay | C9: R [1..*] | D9: Yes | E9: Observation | F9: — | G9: Observation (delay reasons) | H9: code | I9: delay ConceptMap | J9: NV(7701xxx)→data-absent-reason | K9: n/a | L9: EMS Course* | M9: Seeded | N9: Operational; may be excluded from CS
A10: eResponse.13 | B10: EMS Vehicle (Unit) Number | C10: M [1..1] | D10: No | E10: Encounter/Location | F10: — | G10: Encounter.location.location→Location(vehicle) | H10: string→ref | I10: — | J10: NV(7701xxx)→data-absent-reason | K10: n/a | L10: EMS Course* | M10: Mapped
A11: eResponse.14 | B11: EMS Unit Call Sign | C11: M [1..1] | D11: No | E11: Location | F11: — | G11: Location.name/alias (vehicle) | H11: string | I11: n/a | J11: NV(7701xxx)→data-absent-reason | K11: n/a | L11: EMS Course* | M11: Mapped
A12: eResponse.16-.18 | B12: Vehicle Dispatch Location / GPS / USNG | C12: O | D12: No | E12: Location | F12: — | G12: Location.position; Location.address | H12: geo→position | I12: — | J12: NV(7701xxx)→data-absent-reason | K12: n/a | L12: EMS Course* | M12: Seeded
A13: eResponse.19-.22 | B13: Odometer readings (Begin/OnScene/Dest/End) | C13: O | D13: No | E13: Observation | F13: — | G13: Observation (mileage) valueQuantity | H13: decimal→Quantity(mi) | I13: — | J13: NV(7701xxx)→data-absent-reason | K13: n/a | L13: EMS Course* | M13: Seeded | N13: Billing/QA; often excluded from CS
A14: eResponse.23 | B14: Response Mode to Scene | C14: M [1..1] | D14: No | E14: Encounter | F14: — | G14: Encounter.priority | H14: code | I14: priority ConceptMap | J14: NV(7701xxx)→data-absent-reason | K14: n/a | L14: EMS Course* | M14: Mapped | N14: Emergent/non-emergent
A15: eResponse.24 | B15: Additional Response Mode Descriptors | C15: R [1..*] | D15: Yes | E15: Encounter | F15: — | G15: Encounter.priority (ext) | H15: code | I15: ConceptMap | J15: NV(7701xxx)→data-absent-reason | K15: n/a | L15: EMS Course* | M15: Seeded
A16: eDispatch.01 | B16: Dispatch Reason | C16: M [1..1] | D16: No | E16: Encounter / Observation | F16: — | G16: Encounter.reasonCode | H16: code | I16: dispatch-reason ConceptMap→SNOMED | J16: NV(7701xxx)→data-absent-reason | K16: n/a | L16: EMS Course* | M16: Mapped
A17: eDispatch.02 | B17: EMD Performed | C17: R [1..1] | D17: No | E17: Observation | F17: — | G17: Observation (EMD performed) valueBoolean/code | H17: code | I17: — | J17: NV(7701xxx)→data-absent-reason | K17: PN(8801xxx)→statusReason/negation | L17: EMS Course* | M17: Seeded
A18: eDispatch.05 | B18: Dispatch Priority (Patient Acuity) | C18: O | D18: No | E18: Encounter | F18: — | G18: Encounter.priority (dispatch) | H18: code | I18: acuity ConceptMap | J18: NV(7701xxx)→data-absent-reason | K18: n/a | L18: EMS Course* | M18: Seeded
A19: eTimes.01 | B19: PSAP Call Date/Time | C19: R [1..1] | D19: No | E19: Encounter/Observation | F19: — | G19: Provenance.occurred / timeline Observation | H19: dateTime | I19: ISO8601+offset | J19: NV(7701xxx)→data-absent-reason | K19: n/a | L19: EMS Course* | M19: Mapped | N19: Source printed 'EPSAP' (typo)
A20: eTimes.03 | B20: Unit Notified by Dispatch Date/Time | C20: M [1..1] | D20: No | E20: Encounter | F20: US Core Encounter | G20: Encounter.period.start (dispatch phase) | H20: dateTime | I20: ISO8601+offset | J20: n/a | K20: n/a | L20: EMS Course* | M20: Mapped
A21: eTimes.05 | B21: Unit En Route Date/Time | C21: R [1..1] | D21: No | E21: Encounter | F21: — | G21: EncounterHistory / timeline | H21: dateTime | J21: NV(7701xxx)→data-absent-reason | K21: n/a | L21: EMS Course* | M21: Mapped
A22: eTimes.06 | B22: Unit Arrived on Scene Date/Time | C22: R [1..1] | D22: No | E22: Encounter | F22: US Core Encounter | G22: Encounter.period.start (on-scene) | H22: dateTime | J22: NV(7701xxx)→data-absent-reason | K22: n/a | L22: EMS Course* | M22: Mapped | N22: Primary Encounter.period.start
A23: eTimes.07 | B23: Arrived at Patient Date/Time | C23: R [1..1] | D23: No | E23: Encounter/Observation | F23: — | G23: timeline Observation | H23: dateTime | J23: NV(7701xxx)→data-absent-reason | K23: n/a | L23: EMS Course* | M23: Mapped
A24: eTimes.09 | B24: Unit Left Scene Date/Time | C24: R [1..1] | D24: No | E24: Encounter | F24: — | G24: timeline / transport start | H24: dateTime | J24: NV(7701xxx)→data-absent-reason | K24: n/a | L24: EMS Course* | M24: Mapped
A25: eTimes.11 | B25: Patient Arrived at Destination Date/Time | C25: R [1..1] | D25: No | E25: Encounter | F25: US Core Encounter | G25: Encounter.period.end (arrival) | H25: dateTime | J25: NV(7701xxx)→data-absent-reason | K25: n/a | L25: EMS Course* | M25: Mapped
A26: eTimes.12 | B26: Destination Patient Transfer of Care Date/Time | C26: R [1..1] | D26: No | E26: Encounter | F26: US Core Encounter | G26: Encounter.period.end (transfer) | H26: dateTime | J26: NV(7701xxx)→data-absent-reason | K26: n/a | L26: EMS Course* | M26: Mapped | N26: Handoff moment for mPSC-CS
A27: eTimes.02/.04/.08/.10/.13-.17 | B27: Other timeline timestamps | C27: varies | D27: No | E27: Observation/EncounterHistory | F27: — | G27: timeline cluster | H27: dateTime | J27: NV(7701xxx)→data-absent-reason | K27: n/a | L27: EMS Course* | M27: Seeded | N27: Full timeline in CR; subset in CS
A28: eScene.01 | B28: First EMS Unit on Scene | C28: R [1..1] | D28: No | E28: Observation | F28: — | G28: Observation valueBoolean | H28: boolean | I28: — | J28: NV(7701xxx)→data-absent-reason | K28: PN(8801xxx)→statusReason/negation | L28: EMS Course* | M28: Seeded
A29: eScene.06 | B29: Number of Patients at Scene | C29: R [1..1] | D29: No | E29: Observation | F29: — | G29: Observation valueInteger | H29: integer | I29: — | J29: NV(7701xxx)→data-absent-reason | K29: n/a | L29: EMS Course* | M29: Mapped
A30: eScene.07 | B30: Mass Casualty Incident | C30: R [1..1] | D30: No | E30: Observation / Flag | F30: — | G30: Observation (MCI) valueBoolean; Flag | H30: code | I30: — | J30: NV(7701xxx)→data-absent-reason | K30: PN(8801xxx)→statusReason/negation | L30: EMS Course* | M30: Mapped
A31: eScene.08 | B31: Triage Classification for MCI Patient | C31: R [1..1] | D31: No | E31: Observation | F31: — | G31: Observation.value (triage color) | H31: code | I31: 2708xxx ConceptMap (Red/Yellow/Green/Black) | J31: NV(7701xxx)→data-absent-reason | K31: n/a | L31: EMS Course* | M31: Mapped | N31: START/SALT triage
A32: eScene.09 | B32: Incident Location Type | C32: R [1..1] | D32: No | E32: Location | F32: — | G32: Location.type | H32: code | I32: location-type ConceptMap→v3 RoleCode | J32: NV(7701xxx)→data-absent-reason | K32: n/a | L32: EMS Course* | M32: Mapped
A33: eScene.11 | B33: Scene GPS Location | C33: O | D33: No | E33: Location | F33: — | G33: Location.position (lat/long) | H33: geo→position | I33: n/a | J33: NV(7701xxx)→data-absent-reason | K33: n/a | L33: EMS Course* | M33: Mapped
A34: eScene.15-.23 | B34: Incident Address / City / State / ZIP / County / Country / Census | C34: RE/R | D34: No | E34: Location | F34: — | G34: Location.address | H34: address | I34: — | J34: NV(7701xxx)→data-absent-reason | K34: n/a | L34: EMS Course* | M34: Mapped | N34: Scene location resource

Sheet ePatient
A1: ePatient → Patient (US Core / IHE PCC Patient)
A3: NEMSIS ID | B3: NEMSIS Element Name | C3: Usage/Card | D3: Repeats | E3: Target FHIR Resource | F3: Target Profile | G3: FHIR Path | H3: Datatype Transform | I3: Terminology / ConceptMap | J3: NV handling | K3: PN handling | L3: mPSC Section | M3: Status | N3: Notes
A4: ePatient.01 | B4: EMS Patient ID | C4: O [0..1] | D4: No | E4: Patient | F4: IHE.PCC.Patient / US Core Patient | G4: Patient.identifier | H4: string→Identifier | I4: system=agency patient id | J4: NV(7701xxx)→data-absent-reason | K4: n/a | L4: (subject) | M4: Mapped
A5: ePatient.02 | B5: Last Name | C5: RE [0..1] | D5: No | E5: Patient | F5: US Core Patient | G5: Patient.name.family | H5: string | I5: n/a | J5: NV(7701xxx)→data-absent-reason | K5: n/a | L5: (subject) | M5: Mapped | N5: May be unknown at scene
A6: ePatient.03 | B6: First Name | C6: RE [0..1] | D6: No | E6: Patient | F6: US Core Patient | G6: Patient.name.given | H6: string | I6: n/a | J6: NV(7701xxx)→data-absent-reason | K6: n/a | L6: (subject) | M6: Mapped
A7: ePatient.04 | B7: Middle Initial/Name | C7: O | D7: No | E7: Patient | F7: US Core Patient | G7: Patient.name.given[1] | H7: string | I7: n/a | J7: NV(7701xxx)→data-absent-reason | K7: n/a | L7: (subject) | M7: Mapped
A8: ePatient.05-.11 | B8: Home Address/City/County/State/ZIP/Country/Census | C8: O/R | D8: No | E8: Patient | F8: US Core Patient | G8: Patient.address | H8: address | I8: USPS/FIPS | J8: NV(7701xxx)→data-absent-reason | K8: n/a | L8: (subject) | M8: Mapped
A9: ePatient.12 | B9: Social Security Number | C9: O | D9: No | E9: Patient | F9: US Core Patient | G9: Patient.identifier (SSN) | H9: string→Identifier | I9: system=us-ssn | J9: NV(7701xxx)→data-absent-reason | K9: n/a | L9: (subject) | M9: Mapped | N9: PHI — governance-gated
A10: ePatient.13 | B10: Gender (DEPRECATED in 3.5.0) | C10: R [1..1] | D10: No | E10: Patient | F10: US Core Patient | G10: Patient.gender | H10: code | I10: admin-gender ConceptMap | J10: NV(7701xxx)→data-absent-reason | K10: n/a | L10: (subject) | M10: Deferred | N10: LEGACY fallback only — prefer .25 (ADR-007)
A11: ePatient.25 | B11: Sex (replaces .13) | C11: R | D11: No | E11: Patient | F11: US Core Patient | G11: Patient.gender + US Core Sex/birthsex ext | H11: code | I11: admin-gender / birthsex ConceptMap | J11: NV(7701xxx)→data-absent-reason | K11: n/a | L11: (subject) | M11: Mapped | N11: SOURCE OF TRUTH for sex (ADR-007)
A12: ePatient.14 | B12: Race | C12: R [1..*] | D12: Yes | E12: Patient | F12: US Core Patient | G12: Patient.extension (us-core-race) + pcc-uv-race | H12: code | I12: OMB race → CDC Race&Ethnicity ConceptMap | J12: NV(7701xxx)→data-absent-reason | K12: n/a | L12: (subject) | M12: Mapped | N12: Dual-carry US Core + mPSC ext (ADR-006)
A13: ePatient.15 | B13: Age | C13: R [1..1] | D13: No | E13: Patient/Observation | F13: US Core Patient | G13: Patient.birthDate (derive) / Observation age | H13: integer | I13: with .16 units | J13: NV(7701xxx)→data-absent-reason | K13: n/a | L13: (subject) | M13: Mapped | N13: When DOB absent, keep age Observation
A14: ePatient.16 | B14: Age Units | C14: R [1..1] | D14: No | E14: (qualifier) | F14: — | G14: (units for .15) | H14: code | I14: age-unit ConceptMap→UCUM | J14: NV(7701xxx)→data-absent-reason | K14: n/a | L14: (subject) | M14: Mapped | N14: Neonatal: days/hours
A15: ePatient.17 | B15: Date of Birth | C15: RE [0..1] | D15: No | E15: Patient | F15: US Core Patient | G15: Patient.birthDate | H15: date | I15: n/a | J15: NV(7701xxx)→data-absent-reason | K15: n/a | L15: (subject) | M15: Mapped
A16: ePatient.18 | B16: Patient's Phone Number | C16: O [0..*] | D16: Yes | E16: Patient | F16: US Core Patient | G16: Patient.telecom (phone) | H16: contactPoint | I16: n/a | J16: NV(7701xxx)→data-absent-reason | K16: n/a | L16: (subject) | M16: Mapped
A17: ePatient.19 | B17: Patient's Email Address | C17: O [0..*] | D17: Yes | E17: Patient | F17: US Core Patient | G17: Patient.telecom (email) | H17: contactPoint | I17: n/a | J17: NV(7701xxx)→data-absent-reason | K17: n/a | L17: (subject) | M17: Mapped
A18: ePatient.20-.21 | B18: Driver's License State / Number | C18: O | D18: No | E18: Patient | F18: US Core Patient | G18: Patient.identifier (DL) | H18: string→Identifier | I18: system=state DMV | J18: NV(7701xxx)→data-absent-reason | K18: n/a | L18: (subject) | M18: Mapped
A19: ePatient.22 | B19: Alternate Home Residence | C19: RE [0..1] | D19: No | E19: Patient | F19: — | G19: Patient.extension (residence type) | H19: code | I19: residence ConceptMap | J19: NV(7701xxx)→data-absent-reason | K19: n/a | L19: (subject) | M19: Seeded | N19: Homeless/SNF/etc.

Sheet eSituation_eInjury
A1: eSituation · eInjury → Condition / Observation
A3: NEMSIS ID | B3: NEMSIS Element Name | C3: Usage/Card | D3: Repeats | E3: Target FHIR Resource | F3: Target Profile | G3: FHIR Path | H3: Datatype Transform | I3: Terminology / ConceptMap | J3: NV handling | K3: PN handling | L3: mPSC Section | M3: Status | N3: Notes
A4: eSituation.01 | B4: Date/Time of Symptom Onset | C4: R [1..1] | D4: No | E4: Condition | F4: US Core Condition | G4: Condition.onsetDateTime | H4: dateTime | I4: n/a | J4: NV(7701xxx)→data-absent-reason | K4: n/a | L4: Problems | M4: Mapped
A5: eSituation.02 | B5: Possible Injury | C5: R [1..1] | D5: No | E5: Observation/Flag | F5: — | G5: Observation (injury present) valueBoolean | H5: boolean/code | I5: — | J5: NV(7701xxx)→data-absent-reason | K5: PN(8801xxx)→statusReason/negation | L5: Problems | M5: Mapped | N5: Gates eInjury relevance
A6: eSituation.03 | B6: Complaint Type | C6: RE [0..1] | D6: No | E6: Condition | F6: — | G6: Condition.category (chief complaint) | H6: code | I6: ConceptMap | J6: NV(7701xxx)→data-absent-reason | K6: n/a | L6: Problems | M6: Mapped
A7: eSituation.04 | B7: Complaint (chief) | C7: RE [0..1] | D7: No | E7: Condition | F7: US Core Condition | G7: Condition.code (text) / Observation | H7: string/code | I7: free-text or SNOMED | J7: NV(7701xxx)→data-absent-reason | K7: PN(8801xxx)→statusReason/negation | L7: Problems | M7: Mapped | N7: Chief complaint
A8: eSituation.05-.06 | B8: Duration of Complaint + Time Units | C8: RE | D8: No | E8: Condition | F8: — | G8: Condition.onset (derive) / note | H8: integer+unit | I8: UCUM | J8: NV(7701xxx)→data-absent-reason | K8: n/a | L8: Problems | M8: Seeded
A9: eSituation.07 | B9: Chief Complaint Anatomic Location | C9: R [1..1] | D9: No | E9: Condition | F9: — | G9: Condition.bodySite | H9: code | I9: SNOMED body structure | J9: NV(7701xxx)→data-absent-reason | K9: n/a | L9: Problems | M9: Mapped | N9: NOT primary symptom (agent-verified)
A10: eSituation.08 | B10: Chief Complaint Organ System | C10: R [1..1] | D10: No | E10: Condition | F10: — | G10: Condition.bodySite (system) | H10: code | I10: SNOMED | J10: NV(7701xxx)→data-absent-reason | K10: n/a | L10: Problems | M10: Mapped
A11: eSituation.09 | B11: Primary Symptom | C11: R [1..1] | D11: No | E11: Observation/Condition | F11: — | G11: Observation (symptom) / Condition | H11: code | I11: ICD-10-CM (source-coded, pass-through) [corrected 2026-08-06: 3.5.0 XSD pattern-verified; was SNOMED] | J11: NV(7701xxx)→data-absent-reason | K11: PN(8801xxx)→statusReason/negation | L11: Problems | M11: Mapped
A12: eSituation.10 | B12: Other Associated Symptoms | C12: R [1..1] | D12: Yes | E12: Observation | F12: — | G12: Observation (symptoms) | H12: code | I12: ICD-10-CM (source-coded, pass-through) [corrected 2026-08-06: 3.5.0 XSD pattern-verified; was SNOMED] | J12: NV(7701xxx)→data-absent-reason | K12: PN(8801xxx)→statusReason/negation | L12: Problems | M12: Mapped | N12: PN carries pertinent negatives
A13: eSituation.11 | B13: Provider's Primary Impression | C13: R [1..1] | D13: No | E13: Condition | F13: US Core Condition (Encounter Dx) | G13: Condition.code (principal) | H13: code | I13: ICD-10-CM (source-coded, pass-through) [corrected 2026-08-06: 3.5.0 XSD pattern-verified; was SNOMED] | J13: NV(7701xxx)→data-absent-reason | K13: PN(8801xxx)→statusReason/negation | L13: Problems | M13: Mapped | N13: PRINCIPAL condition; ICD-10-CM already in source (3.5.0 XSD-verified)
A14: eSituation.12 | B14: Provider's Secondary Impressions | C14: R [1..1] | D14: Yes | E14: Condition | F14: US Core Condition | G14: Condition.code (additional) | H14: code | I14: ICD-10-CM (source-coded, pass-through) [corrected 2026-08-06: 3.5.0 XSD pattern-verified; was SNOMED] | J14: NV(7701xxx)→data-absent-reason | K14: PN(8801xxx)→statusReason/negation | L14: Problems | M14: Mapped
A15: eSituation.13 | B15: Initial Patient Acuity | C15: R [1..1] | D15: No | E15: Observation | F15: — | G15: Observation (acuity) valueCodeableConcept | H15: code | I15: acuity ConceptMap | J15: NV(7701xxx)→data-absent-reason | K15: n/a | L15: Problems | M15: Mapped
A16: eSituation.14 | B16: Work-Related Illness/Injury | C16: RE [0..1] | D16: No | E16: Observation | F16: — | G16: Observation valueBoolean | H16: boolean | I16: — | J16: NV(7701xxx)→data-absent-reason | K16: PN(8801xxx)→statusReason/negation | L16: Problems | M16: Seeded
A17: eSituation.15-.17 | B17: Occupational Industry / Occupation / Activity | C17: O/RE | D17: No | E17: Observation | F17: US Core Occupation (Odh) | G17: Observation (ODH industry/occupation) | H17: code | I17: ODH ConceptMap | J17: NV(7701xxx)→data-absent-reason | K17: n/a | L17: Social History* | M17: Seeded | N17: Maps to Occupational Data for Health
A18: eSituation.18 | B18: Date/Time Last Known Well | C18: R [1..1] | D18: No | E18: Observation | F18: — | G18: Observation (LKW) valueDateTime | H18: dateTime | I18: stroke-relevant | J18: NV(7701xxx)→data-absent-reason | K18: n/a | L18: Problems | M18: Mapped | N18: Critical for stroke
A19: eSituation.19-.20 | B19: Justification / Reason for Interfacility Transfer | C19: RE/R | D19: No | E19: ServiceRequest/Encounter | F19: — | G19: ServiceRequest.reasonCode; Encounter.reasonCode | H19: code | I19: ConceptMap | J19: NV(7701xxx)→data-absent-reason | K19: n/a | L19: EMS Course* | M19: Mapped | N19: RIPT use case driver
A20: eInjury.01 | B20: Cause of Injury | C20: R [1..*] | D20: Yes | E20: Condition/Observation | F20: — | G20: Condition.code (external cause) | H20: code | I20: ICD-10-CM external cause | J20: NV(7701xxx)→data-absent-reason | K20: n/a | L20: Problems | M20: Mapped
A21: eInjury.02 | B21: Mechanism of Injury | C21: RE [0..*] | D21: Yes | E21: Observation | F21: — | G21: Observation (MOI) | H21: code | I21: SNOMED ConceptMap | J21: NV(7701xxx)→data-absent-reason | K21: PN(8801xxx)→statusReason/negation | L21: Problems | M21: Mapped
A22: eInjury.03 | B22: Trauma Triage Criteria (High Risk) | C22: R [1..*] | D22: Yes | E22: Observation | F22: — | G22: Observation (trauma triage) hasMember | H22: code | I22: CDC field triage ConceptMap | J22: NV(7701xxx)→data-absent-reason | K22: PN(8801xxx)→statusReason/negation | L22: Problems | M22: Mapped | N22: Steps 1-2
A23: eInjury.04 | B23: Trauma Triage Criteria (Moderate Risk) | C23: R [1..*] | D23: Yes | E23: Observation | F23: — | G23: Observation (trauma triage) | H23: code | I23: CDC field triage | J23: NV(7701xxx)→data-absent-reason | K23: PN(8801xxx)→statusReason/negation | L23: Problems | M23: Mapped | N23: Steps 3-4
A24: eInjury.05-.10 | B24: Vehicle impact / seat / safety equip / airbag / fall height / PPE | C24: O/RE | D24: Yes | E24: Observation | F24: — | G24: Observation cluster | H24: mixed | I24: ConceptMaps | J24: NV(7701xxx)→data-absent-reason | K24: PN(8801xxx)→statusReason/negation | L24: Problems | M24: Seeded | N24: Injury detail; CR only
A25: eInjury.11-.29 | B25: ACN telematics (crash notification data) | C25: O | D25: Yes | E25: Observation / DocumentReference | F25: — | G25: Observation cluster or DocumentReference | H25: mixed | I25: — | J25: NV(7701xxx)→data-absent-reason | K25: n/a | L25: Results* | M25: Deferred | N25: Automatic Crash Notification; low field prevalence — CR/attachment

Sheet eArrest
A1: eArrest → Observation / Procedure
A3: NEMSIS ID | B3: NEMSIS Element Name | C3: Usage/Card | D3: Repeats | E3: Target FHIR Resource | F3: Target Profile | G3: FHIR Path | H3: Datatype Transform | I3: Terminology / ConceptMap | J3: NV handling | K3: PN handling | L3: mPSC Section | M3: Status | N3: Notes
A4: eArrest.01 | B4: Cardiac Arrest | C4: R [1..1] | D4: No | E4: Observation | F4: — | G4: Observation (cardiac arrest) valueCodeableConcept | H4: code | I4: yes/no/prior ConceptMap | J4: NV(7701xxx)→data-absent-reason | K4: PN(8801xxx)→statusReason/negation | L4: Problems | M4: Mapped | N4: GATE field; PN=present-prior-to-EMS
A5: eArrest.02 | B5: Cardiac Arrest Etiology | C5: R [1..1] | D5: No | E5: Observation/Condition | F5: — | G5: Condition.code / Observation | H5: code | I5: SNOMED | J5: NV(7701xxx)→data-absent-reason | K5: n/a | L5: Problems | M5: Mapped
A6: eArrest.03 | B6: Resuscitation Attempted By EMS | C6: R [1..*] | D6: Yes | E6: Procedure | F6: — | G6: Procedure (resuscitation) | H6: code | I6: SNOMED | J6: NV(7701xxx)→data-absent-reason | K6: PN(8801xxx)→statusReason/negation | L6: Procedures* | M6: Mapped
A7: eArrest.04 | B7: Arrest Witnessed By | C7: R [1..*] | D7: Yes | E7: Observation | F7: — | G7: Observation valueCodeableConcept | H7: code | I7: ConceptMap | J7: NV(7701xxx)→data-absent-reason | K7: n/a | L7: Problems | M7: Mapped
A8: eArrest.07 | B8: AED Use Prior to EMS Arrival | C8: R [1..1] | D8: No | E8: Procedure/Observation | F8: — | G8: Procedure (AED, performer=other) | H8: code | I8: — | J8: NV(7701xxx)→data-absent-reason | K8: PN(8801xxx)→statusReason/negation | L8: Procedures* | M8: Mapped | N8: Bystander/first responder
A9: eArrest.09 | B9: Type of CPR Provided | C9: R [1..*] | D9: Yes | E9: Procedure | F9: — | G9: Procedure (CPR).code | H9: code | I9: SNOMED | J9: NV(7701xxx)→data-absent-reason | K9: PN(8801xxx)→statusReason/negation | L9: Procedures* | M9: Mapped
A10: eArrest.10 | B10: Therapeutic Hypothermia by EMS | C10: O | D10: No | E10: Procedure | F10: — | G10: Procedure (hypothermia) | H10: code | I10: SNOMED | J10: NV(7701xxx)→data-absent-reason | K10: PN(8801xxx)→statusReason/negation | L10: Procedures* | M10: Seeded
A11: eArrest.11 | B11: First Monitored Arrest Rhythm | C11: R [1..1] | D11: No | E11: Observation | F11: — | G11: Observation (rhythm) valueCodeableConcept | H11: code | I11: rhythm ConceptMap (Asystole/VF/etc.) | J11: NV(7701xxx)→data-absent-reason | K11: n/a | L11: Vitals* | M11: Mapped
A12: eArrest.12 | B12: Any Return of Spontaneous Circulation | C12: R [1..*] | D12: Yes | E12: Observation | F12: — | G12: Observation (ROSC) | H12: code | I12: — | J12: NV(7701xxx)→data-absent-reason | K12: PN(8801xxx)→statusReason/negation | L12: Problems | M12: Mapped
A13: eArrest.14 | B13: Date/Time of Cardiac Arrest | C13: R [1..1] | D13: No | E13: Observation | F13: — | G13: Observation.effectiveDateTime | H13: dateTime | I13: n/a | J13: NV(7701xxx)→data-absent-reason | K13: n/a | L13: Problems | M13: Mapped
A14: eArrest.15 | B14: Date/Time Resuscitation Discontinued | C14: RE [0..1] | D14: No | E14: Procedure | F14: — | G14: Procedure.performedPeriod.end | H14: dateTime | I14: n/a | J14: NV(7701xxx)→data-absent-reason | K14: n/a | L14: Procedures* | M14: Mapped
A15: eArrest.16 | B15: Reason CPR/Resuscitation Discontinued | C15: R [1..1] | D15: No | E15: Procedure | F15: — | G15: Procedure.statusReason / outcome | H15: code | I15: ConceptMap | J15: NV(7701xxx)→data-absent-reason | K15: PN(8801xxx)→statusReason/negation | L15: Procedures* | M15: Mapped
A16: eArrest.17 | B16: Cardiac Rhythm on Arrival at Destination | C16: R [1..*] | D16: Yes | E16: Observation | F16: — | G16: Observation (rhythm at dest) | H16: code | I16: rhythm ConceptMap | J16: NV(7701xxx)→data-absent-reason | K16: n/a | L16: Vitals* | M16: Mapped
A17: eArrest.18 | B17: End of EMS Cardiac Arrest Event | C17: R [1..1] | D17: No | E17: Observation | F17: — | G17: Observation valueCodeableConcept | H17: code | I17: ConceptMap | J17: NV(7701xxx)→data-absent-reason | K17: n/a | L17: Problems | M17: Mapped
A18: eArrest.19-.22 | B18: CPR/AED/Defib initiation timing + who first | C18: O/R | D18: No | E18: Procedure | F18: — | G18: Procedure.performer / performedDateTime | H18: mixed | I18: — | J18: NV(7701xxx)→data-absent-reason | K18: PN(8801xxx)→statusReason/negation | L18: Procedures* | M18: Seeded | N18: Note: eArrest.05/.06/.08 do not exist in 3.5

Sheet eHistory
A1: eHistory → Condition / AllergyIntolerance / MedicationStatement / Consent
A3: NEMSIS ID | B3: NEMSIS Element Name | C3: Usage/Card | D3: Repeats | E3: Target FHIR Resource | F3: Target Profile | G3: FHIR Path | H3: Datatype Transform | I3: Terminology / ConceptMap | J3: NV handling | K3: PN handling | L3: mPSC Section | M3: Status | N3: Notes
A4: eHistory.01 | B4: Barriers to Patient Care | C4: R [1..*] | D4: Yes | E4: Observation | F4: — | G4: Observation (barrier) | H4: code | I4: ConceptMap (language/cultural/etc.) | J4: NV(7701xxx)→data-absent-reason | K4: PN(8801xxx)→statusReason/negation | L4: Social History* | M4: Mapped
A5: eHistory.02-.04 | B5: Patient's Practitioner Name | C5: O | D5: No | E5: Practitioner/RelatedPerson | F5: — | G5: Patient.generalPractitioner→Practitioner | H5: name | I5: — | J5: NV(7701xxx)→data-absent-reason | K5: n/a | L5: (subject) | M5: Seeded
A6: eHistory.05 | B6: Advance Directives | C6: RE [0..*] | D6: Yes | E6: Consent / DocumentReference | F6: — | G6: Consent (advance directive) | H6: code | I6: ConceptMap (DNR/POLST) | J6: NV(7701xxx)→data-absent-reason | K6: PN(8801xxx)→statusReason/negation | L6: Advance Directives* | M6: Mapped | N6: DNR/POLST clinically critical
A7: eHistory.06 | B7: Medication Allergies | C7: RE [0..*] | D7: Yes | E7: AllergyIntolerance | F7: US Core AllergyIntolerance | G7: AllergyIntolerance.code (category=medication) | H7: code | I7: RxNorm/SNOMED | J7: NV(7701xxx)→data-absent-reason | K7: PN(8801xxx)→statusReason/negation | L7: Allergies | M7: Mapped | N7: PN=No Known Drug Allergy (8801013)
A8: eHistory.07 | B8: Environmental/Food Allergies | C8: O [0..*] | D8: Yes | E8: AllergyIntolerance | F8: US Core AllergyIntolerance | G8: AllergyIntolerance.code (category=environment/food) | H8: code | I8: SNOMED | J8: NV(7701xxx)→data-absent-reason | K8: PN(8801xxx)→statusReason/negation | L8: Allergies | M8: Mapped
A9: eHistory.08 | B9: Medical/Surgical History | C9: RE [0..*] | D9: Yes | E9: Condition | F9: US Core Condition (Problem) | G9: Condition.code (category=problem-list) | H9: code | I9: ICD-10-CM (source-coded, pass-through) [corrected 2026-08-06: 3.5.0 XSD pattern-verified; was SNOMED] | J9: NV(7701xxx)→data-absent-reason | K9: PN(8801xxx)→statusReason/negation | L9: Problems | M9: Mapped | N9: Feeds Problems section
A10: eHistory.09 | B10: Medical History Obtained From | C10: O [0..*] | D10: Yes | E10: Provenance | F10: — | G10: Provenance.agent / Condition.asserter | H10: code | I10: source ConceptMap | J10: NV(7701xxx)→data-absent-reason | K10: n/a | L10: Problems | M10: Seeded
A11: eHistory.10-.11 | B11: Immunization Type + Year | C11: O | D11: No | E11: Immunization | F11: US Core Immunization | G11: Immunization.vaccineCode; occurrence | H11: code/date | I11: CVX ConceptMap | J11: NV(7701xxx)→data-absent-reason | K11: PN(8801xxx)→statusReason/negation | L11: Immunizations* | M11: Seeded | N11: Sparse in field data
A12: eHistory.12 | B12: Current Medications | C12: RE [0..1] | D12: Yes | E12: MedicationStatement | F12: US Core Medication | G12: MedicationStatement.medication (home meds) | H12: code | I12: RxNorm | J12: NV(7701xxx)→data-absent-reason | K12: PN(8801xxx)→statusReason/negation | L12: Medication Summary | M12: Mapped | N12: Home meds → Med Summary section
A13: eHistory.13-.15,.20 | B13: Current Med Dose/Unit/Route/Frequency | C13: O | D13: Yes | E13: MedicationStatement | F13: US Core Medication | G13: MedicationStatement.dosage | H13: dosage | I13: UCUM/SNOMED route | J13: NV(7701xxx)→data-absent-reason | K13: n/a | L13: Medication Summary | M13: Seeded
A14: eHistory.16 | B14: Presence of Emergency Information Form | C14: O | D14: No | E14: DocumentReference | F14: — | G14: DocumentReference (EIF) | H14: code | I14: — | J14: NV(7701xxx)→data-absent-reason | K14: n/a | L14: (header) | M14: Seeded
A15: eHistory.17 | B15: Alcohol/Drug Use Indicators | C15: R [1..*] | D15: Yes | E15: Observation | F15: US Core Smoking/Social | G15: Observation (substance use) | H15: code | I15: SNOMED | J15: NV(7701xxx)→data-absent-reason | K15: PN(8801xxx)→statusReason/negation | L15: Social History* | M15: Mapped
A16: eHistory.18 | B16: Pregnancy | C16: O | D16: No | E16: Observation | F16: US Core Pregnancy Status | G16: Observation (pregnancy status) | H16: code | I16: LOINC 82810-3 | J16: NV(7701xxx)→data-absent-reason | K16: PN(8801xxx)→statusReason/negation | L16: Problems | M16: Mapped
A17: eHistory.19 | B17: Last Oral Intake | C17: O | D17: No | E17: Observation | F17: — | G17: Observation valueDateTime | H17: dateTime | I17: — | J17: NV(7701xxx)→data-absent-reason | K17: n/a | L17: Problems | M17: Mapped | N17: Anesthesia-relevant

Sheet eVitals
A1: eVitals → Observation (US Core Vital Signs)
A3: NEMSIS ID | B3: NEMSIS Element Name | C3: Usage/Card | D3: Repeats | E3: Target FHIR Resource | F3: Target Profile | G3: FHIR Path | H3: Datatype Transform | I3: Terminology / ConceptMap | J3: NV handling | K3: PN handling | L3: mPSC Section | M3: Status | N3: Notes
A4: eVitals.01 | B4: Date/Time Vital Signs Taken | C4: R [1..1] | D4: Yes(group) | E4: Observation | F4: US Core Vital Signs | G4: Observation.effectiveDateTime (ALL in group) | H4: dateTime | I4: n/a | J4: NV(7701xxx)→data-absent-reason | K4: n/a | L4: Vital Signs* | M4: Mapped | N4: GROUP timestamp shared by all Observations from this VitalGroup
A5: eVitals.02 | B5: Obtained Prior to this Unit's EMS Care | C5: R [1..1] | D5: Yes | E5: (provenance) | F5: — | G5: Observation.performer / Provenance (prior unit) | H5: boolean | I5: — | J5: NV(7701xxx)→data-absent-reason | K5: PN(8801xxx)→statusReason/negation | L5: Vital Signs* | M5: Mapped | N5: Provenance flag, NOT a measured value
A6: eVitals.03 | B6: Cardiac Rhythm / ECG | C6: R [1..*] | D6: Yes | E6: Observation | F6: — | G6: Observation (ECG rhythm) | H6: code | I6: rhythm ConceptMap | J6: NV(7701xxx)→data-absent-reason | K6: PN(8801xxx)→statusReason/negation | L6: Vital Signs* | M6: Mapped
A7: eVitals.04-.05 | B7: ECG Type / Method of Interpretation | C7: R | D7: Yes | E7: Observation | F7: — | G7: Observation.method / component | H7: code | I7: ConceptMap | J7: NV(7701xxx)→data-absent-reason | K7: n/a | L7: Vital Signs* | M7: Seeded
A8: eVitals.06 | B8: SBP (Systolic Blood Pressure) | C8: R [1..1] | D8: Yes | E8: Observation | F8: US Core Blood Pressure | G8: Observation component LOINC 8480-6, mmHg | H8: integer→Quantity | I8: LOINC 85354-9 panel | J8: NV(7701xxx)→data-absent-reason | K8: PN(8801xxx)→statusReason/negation | L8: Vital Signs* | M8: Mapped
A9: eVitals.07 | B9: DBP (Diastolic Blood Pressure) | C9: RE [0..1] | D9: Yes | E9: Observation | F9: US Core Blood Pressure | G9: Observation component LOINC 8462-4, mmHg | H9: integer→Quantity | I9: LOINC | J9: NV(7701xxx)→data-absent-reason | K9: PN(8801xxx)→statusReason/negation | L9: Vital Signs* | M9: Mapped | N9: Same BP Observation as .06
A10: eVitals.08 | B10: Method of Blood Pressure Measurement | C10: RE [0..1] | D10: Yes | E10: Observation | F10: — | G10: Observation.method | H10: code | I10: SNOMED | J10: NV(7701xxx)→data-absent-reason | K10: n/a | L10: Vital Signs* | M10: Mapped
A11: eVitals.09 | B11: Mean Arterial Pressure | C11: O | D11: Yes | E11: Observation | F11: — | G11: Observation LOINC 8478-0 | H11: integer→Quantity | I11: LOINC | J11: NV(7701xxx)→data-absent-reason | K11: n/a | L11: Vital Signs* | M11: Seeded
A12: eVitals.10 | B12: Heart Rate | C12: R [1..1] | D12: Yes | E12: Observation | F12: US Core Heart Rate | G12: Observation LOINC 8867-4, /min | H12: integer→Quantity | I12: LOINC | J12: NV(7701xxx)→data-absent-reason | K12: PN(8801xxx)→statusReason/negation | L12: Vital Signs* | M12: Mapped
A13: eVitals.12 | B13: Pulse Oximetry | C13: R [1..1] | D13: Yes | E13: Observation | F13: US Core Pulse Oximetry | G13: Observation LOINC 2708-6/59408-5, % | H13: integer→Quantity | I13: LOINC | J13: NV(7701xxx)→data-absent-reason | K13: PN(8801xxx)→statusReason/negation | L13: Vital Signs* | M13: Mapped
A14: eVitals.14 | B14: Respiratory Rate | C14: R [1..1] | D14: Yes | E14: Observation | F14: US Core Respiratory Rate | G14: Observation LOINC 9279-1, /min | H14: integer→Quantity | I14: LOINC | J14: NV(7701xxx)→data-absent-reason | K14: PN(8801xxx)→statusReason/negation | L14: Vital Signs* | M14: Mapped
A15: eVitals.16 | B15: End Tidal CO2 (ETCO2) | C15: R [1..1] | D15: Yes | E15: Observation | F15: — | G15: Observation LOINC 19889-5, mmHg | H15: integer→Quantity | I15: LOINC | J15: NV(7701xxx)→data-absent-reason | K15: PN(8801xxx)→statusReason/negation | L15: Vital Signs* | M15: Mapped
A16: eVitals.17 | B16: Carbon Monoxide (CO) | C16: RE [0..1] | D16: Yes | E16: Observation | F16: — | G16: Observation (SpCO) valueQuantity % | H16: integer→Quantity | I16: LOINC | J16: NV(7701xxx)→data-absent-reason | K16: PN(8801xxx)→statusReason/negation | L16: Vital Signs* | M16: Seeded
A17: eVitals.18 | B17: Blood Glucose Level | C17: R [1..1] | D17: Yes | E17: Observation | F17: US Core Lab/Vital | G17: Observation LOINC 2339-0, mg/dL | H17: integer→Quantity | I17: LOINC | J17: NV(7701xxx)→data-absent-reason | K17: PN(8801xxx)→statusReason/negation | L17: Vital Signs* | M17: Mapped
A18: eVitals.19-.23 | B18: Glasgow Coma Score (Eye/Verbal/Motor/Qualifier/Total) | C18: R/RE | D18: Yes | E18: Observation | F18: — | G18: Observation LOINC 9269-2 (total) + components 9267-6/9270-0/9268-4 | H18: integer→Quantity/panel | I18: LOINC GCS panel; helper aggregates total | J18: NV(7701xxx)→data-absent-reason | K18: PN(8801xxx)→statusReason/negation | L18: Vital Signs* | M18: Mapped | N18: Helper computes/validates total from components
A19: eVitals.24-.25 | B19: Temperature + Method | C19: RE/O | D19: Yes | E19: Observation | F19: US Core Body Temperature | G19: Observation LOINC 8310-5, Cel | H19: decimal→Quantity | I19: LOINC; UCUM Cel/[degF] | J19: NV(7701xxx)→data-absent-reason | K19: PN(8801xxx)→statusReason/negation | L19: Vital Signs* | M19: Mapped
A20: eVitals.26 | B20: Level of Responsiveness (AVPU) | C20: R [1..1] | D20: Yes | E20: Observation | F20: — | G20: Observation valueCodeableConcept | H20: code | I20: AVPU ConceptMap→SNOMED | J20: NV(7701xxx)→data-absent-reason | K20: PN(8801xxx)→statusReason/negation | L20: Vital Signs* | M20: Mapped
A21: eVitals.27-.28 | B21: Pain Scale Score + Type | C21: R/RE | D21: Yes | E21: Observation | F21: — | G21: Observation LOINC 72514-3 + method | H21: integer→Quantity | I21: LOINC; scale-type ConceptMap | J21: NV(7701xxx)→data-absent-reason | K21: PN(8801xxx)→statusReason/negation | L21: Vital Signs* | M21: Mapped
A22: eVitals.29-.30 | B22: Stroke Scale Score + Type | C22: R [1..1] | D22: Yes | E22: Observation | F22: — | G22: Observation (stroke scale) + method | H22: code/score | I22: Cincinnati/LAMS/etc. ConceptMap | J22: NV(7701xxx)→data-absent-reason | K22: PN(8801xxx)→statusReason/negation | L22: Vital Signs* | M22: Mapped | N22: Stroke system-of-care
A23: eVitals.31 | B23: Reperfusion Checklist | C23: R [1..1] | D23: Yes | E23: Observation | F23: — | G23: Observation (STEMI reperfusion) | H23: code | I23: ConceptMap | J23: NV(7701xxx)→data-absent-reason | K23: PN(8801xxx)→statusReason/negation | L23: Vital Signs* | M23: Seeded
A24: eVitals.32 | B24: APGAR | C24: O | D24: Yes | E24: Observation | F24: — | G24: Observation LOINC 9272-6 panel | H24: integer | I24: LOINC APGAR | J24: NV(7701xxx)→data-absent-reason | K24: n/a | L24: Vital Signs* | M24: Seeded | N24: Neonatal
A25: eVitals.33 | B25: Revised Trauma Score | C25: O | D25: Yes | E25: Observation | F25: — | G25: Observation (RTS) valueQuantity | H25: integer | I25: — | J25: NV(7701xxx)→data-absent-reason | K25: n/a | L25: Vital Signs* | M25: Seeded

Sheet eMedications
A1: eMedications → MedicationAdministration (RxNorm)
A3: NEMSIS ID | B3: NEMSIS Element Name | C3: Usage/Card | D3: Repeats | E3: Target FHIR Resource | F3: Target Profile | G3: FHIR Path | H3: Datatype Transform | I3: Terminology / ConceptMap | J3: NV handling | K3: PN handling | L3: mPSC Section | M3: Status | N3: Notes
A4: eMedications.01 | B4: Date/Time Medication Administered | C4: R [1..1] | D4: Yes(group) | E4: MedicationAdministration | F4: US Core MedicationAdministration | G4: MedicationAdministration.effectiveDateTime | H4: dateTime | I4: n/a | J4: NV(7701xxx)→data-absent-reason | K4: n/a | L4: Medication Summary | M4: Mapped | N4: GROUP timestamp
A5: eMedications.02 | B5: Administered Prior to this Unit's EMS Care | C5: R [1..1] | D5: Yes | E5: MedicationAdministration | F5: US Core MedAdmin | G5: MedicationAdministration.performer / Provenance | H5: boolean | I5: — | J5: NV(7701xxx)→data-absent-reason | K5: PN(8801xxx)→statusReason/negation | L5: Medication Summary | M5: Mapped | N5: Prior-unit provenance kept distinct
A6: eMedications.03 | B6: Medication Administered | C6: R [1..1] | D6: Yes | E6: MedicationAdministration | F6: US Core MedAdmin | G6: MedicationAdministration.medicationCodeableConcept | H6: code | I6: RxNorm (source-coded, pass-through) | J6: NV(7701xxx)→data-absent-reason | K6: PN(8801xxx)→statusReason/negation | L6: Medication Summary | M6: Mapped | N6: PN=not given (contraindicated/refused)→statusReason + status=not-done
A7: eMedications.04 | B7: Medication Administered Route | C7: R [1..1] | D7: Yes | E7: MedicationAdministration | F7: US Core MedAdmin | G7: MedicationAdministration.dosage.route | H7: code | I7: route ConceptMap→SNOMED (9927xxx) | J7: NV(7701xxx)→data-absent-reason | K7: n/a | L7: Medication Summary | M7: Mapped
A8: eMedications.05 | B8: Medication Dosage | C8: R [1..1] | D8: Yes | E8: MedicationAdministration | F8: US Core MedAdmin | G8: MedicationAdministration.dosage.dose.value | H8: decimal→Quantity | I8: with .06 units | J8: NV(7701xxx)→data-absent-reason | K8: PN(8801xxx)→statusReason/negation | L8: Medication Summary | M8: Mapped
A9: eMedications.06 | B9: Medication Dosage Units | C9: R [1..1] | D9: Yes | E9: MedicationAdministration | F9: US Core MedAdmin | G9: MedicationAdministration.dosage.dose.unit | H9: code | I9: UCUM ConceptMap | J9: NV(7701xxx)→data-absent-reason | K9: n/a | L9: Medication Summary | M9: Mapped
A10: eMedications.07 | B10: Response to Medication | C10: R [1..1] | D10: Yes | E10: Observation | F10: — | G10: Observation (response) derivedFrom MedAdmin | H10: code | I10: ConceptMap | J10: NV(7701xxx)→data-absent-reason | K10: PN(8801xxx)→statusReason/negation | L10: Medication Summary | M10: Mapped
A11: eMedications.08 | B11: Medication Complication | C11: R [1..1] | D11: Yes | E11: MedicationAdministration | F11: US Core MedAdmin | G11: MedicationAdministration.note / Observation | H11: code | I11: SNOMED | J11: NV(7701xxx)→data-absent-reason | K11: PN(8801xxx)→statusReason/negation | L11: Medication Summary | M11: Mapped | N11: PN=none
A12: eMedications.09 | B12: Medication Crew ID | C12: RE [0..1] | D12: Yes | E12: MedicationAdministration | F12: — | G12: MedicationAdministration.performer.actor→Practitioner | H12: ref | I12: →dPersonnel/eCrew | J12: NV(7701xxx)→data-absent-reason | K12: n/a | L12: Medication Summary | M12: Mapped
A13: eMedications.10 | B13: Role/Type of Person Administering | C13: R [1..1] | D13: Yes | E13: MedicationAdministration | F13: — | G13: MedicationAdministration.performer.function | H13: code | I13: ConceptMap | J13: NV(7701xxx)→data-absent-reason | K13: n/a | L13: Medication Summary | M13: Mapped
A14: eMedications.11-.12 | B14: Medication Authorization / Authorizing Physician | C14: O | D14: Yes | E14: MedicationAdministration | F14: — | G14: MedicationAdministration.request / performer | H14: code/ref | I14: online/offline medical control | J14: NV(7701xxx)→data-absent-reason | K14: n/a | L14: Medication Summary | M14: Seeded

Sheet eProcedures_eAirway
A1: eProcedures · eAirway → Procedure (SNOMED)
A3: NEMSIS ID | B3: NEMSIS Element Name | C3: Usage/Card | D3: Repeats | E3: Target FHIR Resource | F3: Target Profile | G3: FHIR Path | H3: Datatype Transform | I3: Terminology / ConceptMap | J3: NV handling | K3: PN handling | L3: mPSC Section | M3: Status | N3: Notes
A4: eProcedures.01 | B4: Date/Time Procedure Performed | C4: R [1..1] | D4: Yes(group) | E4: Procedure | F4: US Core Procedure | G4: Procedure.performedDateTime | H4: dateTime | I4: n/a | J4: NV(7701xxx)→data-absent-reason | K4: n/a | L4: Procedures* | M4: Mapped | N4: GROUP timestamp
A5: eProcedures.02 | B5: Performed Prior to this Unit's EMS Care | C5: R [1..1] | D5: Yes | E5: Procedure | F5: US Core Procedure | G5: Procedure.performer / Provenance | H5: boolean | I5: — | J5: NV(7701xxx)→data-absent-reason | K5: PN(8801xxx)→statusReason/negation | L5: Procedures* | M5: Mapped | N5: Prior-unit provenance kept distinct
A6: eProcedures.03 | B6: Procedure | C6: R [1..1] | D6: Yes | E6: Procedure | F6: US Core Procedure | G6: Procedure.code | H6: code | I6: SNOMED (source-coded, pass-through) | J6: NV(7701xxx)→data-absent-reason | K6: PN(8801xxx)→statusReason/negation | L6: Procedures* | M6: Mapped | N6: PN=not performed→status=not-done + statusReason
A7: eProcedures.04 | B7: Size of Procedure Equipment | C7: O | D7: Yes | E7: Procedure/Device | F7: — | G7: Procedure.usedCode / focalDevice | H7: code/Quantity | I7: — | J7: NV(7701xxx)→data-absent-reason | K7: n/a | L7: Procedures* | M7: Seeded
A8: eProcedures.05 | B8: Number of Procedure Attempts | C8: R [1..1] | D8: Yes | E8: Procedure/Observation | F8: — | G8: Observation (attempts) / Procedure.note | H8: integer | I8: — | J8: NV(7701xxx)→data-absent-reason | K8: n/a | L8: Procedures* | M8: Mapped
A9: eProcedures.06 | B9: Procedure Successful | C9: R [1..1] | D9: Yes | E9: Procedure | F9: US Core Procedure | G9: Procedure.outcome | H9: code | I9: success ConceptMap | J9: NV(7701xxx)→data-absent-reason | K9: PN(8801xxx)→statusReason/negation | L9: Procedures* | M9: Mapped
A10: eProcedures.07 | B10: Procedure Complication | C10: R [1..*] | D10: Yes | E10: Procedure | F10: US Core Procedure | G10: Procedure.complication | H10: code | I10: NEMSIS 3907xxx ConceptMap + dual-code [corrected 2026-08-06: 3.5.0 XSD enumeration; was SNOMED] | J10: NV(7701xxx)→data-absent-reason | K10: PN(8801xxx)→statusReason/negation | L10: Procedures* | M10: Mapped | N10: PN=none
A11: eProcedures.08 | B11: Response to Procedure | C11: R [1..1] | D11: Yes | E11: Observation | F11: — | G11: Observation (response) derivedFrom Procedure | H11: code | I11: ConceptMap | J11: NV(7701xxx)→data-absent-reason | K11: PN(8801xxx)→statusReason/negation | L11: Procedures* | M11: Mapped
A12: eProcedures.09 | B12: Procedure Crew Members ID | C12: RE [0..1] | D12: Yes | E12: Procedure | F12: US Core Procedure | G12: Procedure.performer.actor→Practitioner | H12: ref | I12: →dPersonnel/eCrew | J12: NV(7701xxx)→data-absent-reason | K12: n/a | L12: Procedures* | M12: Mapped
A13: eProcedures.10 | B13: Role/Type of Person Performing | C13: R [1..1] | D13: Yes | E13: Procedure | F13: — | G13: Procedure.performer.function | H13: code | I13: ConceptMap | J13: NV(7701xxx)→data-absent-reason | K13: n/a | L13: Procedures* | M13: Mapped
A14: eProcedures.11-.12 | B14: Procedure Authorization / Authorizing Physician | C14: O | D14: Yes | E14: Procedure | F14: — | G14: Procedure.basedOn / performer | H14: code/ref | I14: medical control | J14: NV(7701xxx)→data-absent-reason | K14: n/a | L14: Procedures* | M14: Seeded
A15: eProcedures.13 | B15: Vascular Access Location | C15: RE [0..1] | D15: Yes | E15: Procedure | F15: US Core Procedure | G15: Procedure.bodySite | H15: code | I15: SNOMED body structure | J15: NV(7701xxx)→data-absent-reason | K15: n/a | L15: Procedures* | M15: Mapped
A16: eAirway.01 | B16: Indications for Invasive Airway | C16: RE [0..*] | D16: Yes | E16: Procedure/Observation | F16: — | G16: Procedure.reasonCode | H16: code | I16: SNOMED | J16: NV(7701xxx)→data-absent-reason | K16: PN(8801xxx)→statusReason/negation | L16: Procedures* | M16: Mapped
A17: eAirway.02-.04 | B17: Airway Device Confirmation (time/device/method) | C17: RE | D17: Yes | E17: Procedure/Observation | F17: — | G17: Procedure + Observation (confirmation) | H17: mixed | I17: SNOMED | J17: NV(7701xxx)→data-absent-reason | K17: PN(8801xxx)→statusReason/negation | L17: Procedures* | M17: Mapped | N17: Links to eProcedures airway entry
A18: eAirway.05 | B18: Tube Depth | C18: O | D18: Yes | E18: Observation | F18: — | G18: Observation valueQuantity (cm) | H18: decimal→Quantity | I18: UCUM cm | J18: NV(7701xxx)→data-absent-reason | K18: n/a | L18: Procedures* | M18: Seeded
A19: eAirway.06-.11 | B19: Confirming person / complications / failed-airway reasons / decision & abandon times | C19: O/RE | D19: Yes | E19: Procedure/Observation | F19: — | G19: Procedure.performer / complication / statusReason; timing | H19: mixed | I19: ConceptMaps | J19: NV(7701xxx)→data-absent-reason | K19: PN(8801xxx)→statusReason/negation | L19: Procedures* | M19: Seeded

Sheet eExam_eLabs_eDevice
A1: eExam · eProtocols · eLabs · eDevice → Observation / DiagnosticReport / Media
A3: NEMSIS ID | B3: NEMSIS Element Name | C3: Usage/Card | D3: Repeats | E3: Target FHIR Resource | F3: Target Profile | G3: FHIR Path | H3: Datatype Transform | I3: Terminology / ConceptMap | J3: NV handling | K3: PN handling | L3: mPSC Section | M3: Status | N3: Notes
A4: eExam.01 | B4: Estimated Body Weight (kg) | C4: RE [0..1] | D4: No | E4: Observation | F4: US Core Body Weight | G4: Observation LOINC 29463-7, kg | H4: decimal→Quantity | I4: LOINC/UCUM | J4: NV(7701xxx)→data-absent-reason | K4: PN(8801xxx)→statusReason/negation | L4: Vital Signs* | M4: Mapped
A5: eExam.02 | B5: Length Based Tape Measure | C5: RE [0..1] | D5: No | E5: Observation | F5: — | G5: Observation (Broselow) valueCodeableConcept | H5: code | I5: color ConceptMap; helper for peds weight | J5: NV(7701xxx)→data-absent-reason | K5: n/a | L5: Vital Signs* | M5: Mapped | N5: Pediatric length-based dosing
A6: eExam.03 | B6: Date/Time of Assessment | C6: O | D6: Yes(group) | E6: Observation | F6: — | G6: Observation.effectiveDateTime (exam group) | H6: dateTime | I6: n/a | J6: NV(7701xxx)→data-absent-reason | K6: n/a | L6: (exam) | M6: Mapped | N6: Exam group timestamp
